Workbook

Sheet AFA
B4: ) DADOS DA SOLICITAÇÃO
B5: Identificação do órgão ou entidade a ser atendido | D5: Código SIORG
B6: Ministério da Defesa | D6: 41066
B7: Comando da Aeronáutica | D7: 48
B8: Academia da Força Aérea | D8: 145
B9: Quadro-resumo da demanda | F9: Impacto Orçamentário Anual
B10: Cargo | C10: Remuneração | E10: Qtd | F10: 2026 | G10: 2027 | H10: 2028
B11: Bibliotecário | C11: 7159.87 | E11: 1 | F11: 86769.43 | G11: 118333.49 | H11: 118333.49
B12: Nutricionista | C12: 7159.87 | E12: 1 | F12: 86769.43 | G12: 118333.49 | H12: 118333.49
B13: Professor Magistério Superior | C13: 13753.96 | E13: 34 | F13: 5448096.4 | G13: 7446709.6 | H13: 7446709.6
B14: Advogado | C14: 7159.87 | E14: 2 | F14: 173538.86 | G14: 236666.98 | H14: 236666.98
B15: Médico Oftalmologista | C15: 5613.57 | E15: 1 | F15: 69582.94 | G15: 94856.06 | H15: 94856.06
B16: Médico Urologista | C16: 5613.57 | E16: 1 | F16: 69582.94 | G16: 94856.06 | H16: 94856.06
B17: Médico Psiquiatra | C17: 5613.57 | E17: 1 | F17: 69582.94 | G17: 94856.06 | H17: 94856.06
B18: Médico Pediatra | C18: 5613.57 | E18: 1 | F18: 69582.94 | G18: 94856.06 | H18: 94856.06
B19: Médico Anestesiologista | C19: 5613.57 | E19: 1 | F19: 69582.94 | G19: 94856.06 | H19: 94856.06
B20: Terapeuta Ocupacional | C20: 7159.87 | E20: 1 | F20: 86769.43 | G20: 118333.49 | H20: 118333.49
B21: Técnico em Radiologia | C21: 4787.47 | E21: 1 | F21: 60409.05 | G21: 82414.12 | H21: 82414.12
B22: Contador | C22: 7159.87 | E22: 2 | F22: 173538.86 | G22: 236666.98 | H22: 236666.98
... B40: Total | C40: 120751.06 | E40: 80 | F40: 9011970.1 | G40: 12307900 | H40: 12307900

Sheet AFA - IMPACTO
A1: IMPACTO ORÇAMENTÁRIO E FINANCEIRO - AFA
A2: Parâmetros para cálculo do impacto orçamentário com pessoal
A3: (Memória de Cálculo)
A4: PREVISÃO ORÇAMENTÁRIA 2026 (ABR A DEZ)
A6: PROFISSIONAIS | B6: NÍVEL | C6: QTD | D6: VENC BÁSICO | E6: GDPGPE | F6: REMUN INDIV | G6: ENC. SOCIAIS/A | H6: AUX ALIM | I6: AUX TRANS | J6: CUSTO MENSAL | K6: CUSTO 09 MESES | L6: GRAT. NATALINA | M6: AD. FÉRIAS | N6: ENC. SOCIAIS/B | O6: CUSTO ANUAL INDIV | P6: CUSTO ANUAL TOTAL
C7: A | D7: B | E7: C | F7: (B+C) D | G7: E | H7: F | I7: G | J7: (D+E+F+G) | K7: (H*09) | L7: (D) J | M7: (D/3) K | N7: L | O7: (I+J+K+L) M | P7: (A*M) N
J8: H | K8: I
A9: Bibliotecário | B9: NS | C9: 1 | D9: 2769.57 | E9: 4390.3 | F9: 7159.87 | G9: 821.15 | H9: 1000 | I9: - | J9: 8981.02 | K9: 80829.18 | L9: 5369.68 | M9: 0 | N9: 570.57 | O9: 86769.43 | P9: 86769.43
A10: TOTAL | D10: 2769.57 | E10: 4390.3 | F10: 7159.87 | G10: 821.15 | H10: 1000 | I10: - | J10: 8981.02 | K10: 80829.18 | L10: 5369.68 | M10: 0 | N10: 570.57 | O10: 86769.43 | P10: 86769.43
A11: PROFISSIONAIS | B11: NÍVEL | C11: QTD | D11: VENC BÁSICO | E11: GDPGPE | F11: REMUN INDIV | G11: ENC. SOCIAIS/A | H11: AUX ALIM | I11: AUX TRANS | J11: CUSTO MENSAL | K11: CUSTO09 MESES | L11: GRAT. NATALINA | M11: AD. FÉRIAS | N11: ENC. SOCIAIS/B | O11: CUSTO ANUAL INDIV | P11: CUSTO ANUAL TOTAL
C12: A | D12: B | E12: C | F12: (B+C) D | G12: E | H12: F | I12: G | J12: (D+E+F+G) | K12: (H*09) | L12: (D) J | M12: (D/3) K | N12: L | O12: (I+J+K+L) M | P12: (A*M) N
J13: H | K13: I
A14: Nutricionista | B14: NS | C14: 1 | D14: 2769.57 | E14: 4390.3 | F14: 7159.87 | G14: 821.15 | H14: 1000 | I14: - | J14: 8981.02 | K14: 80829.18 | L14: 5369.68 | M14: 0 | N14: 570.57 | O14: 86769.43 | P14: 86769.43
A15: TOTAL | D15: 2769.57 | E15: 4390.3 | F15: 7159.87 | G15: 821.15 | H15: 1000 | I15: - | J15: 8981.02 | K15: 80829.18 | L15: 5369.68 | M15: 0 | N15: 570.57 | O15: 86769.43 | P15: 86769.43
A16: PROFISSIONAIS | B16: NÍVEL | C16: QTD | D16: VENC BÁSICO | E16: RT | F16: REMUN INDIV | G16: ENC. SOCIAIS/A | H16: AUX ALIM | I16: AUX TRANS | J16: CUSTO MENSAL | K16: CUSTO 09 MESES | L16: GRAT. NATALINA | M16: AD. FÉRIAS | N16: ENC. SOCIAIS/B | O16: CUSTO ANUAL INDIV | P16: CUSTO ANUAL TOTAL
C17: A | D17: B | E17: C | F17: (B+C) D | G17: E | H17: F | I17: G | J17: (D+E+F+G) | K17: (H*09) | L17: (D) J | M17: (D/3) K | N17: L | O17: (I+J+K+L) M | P17: (A*M) N
J18: H | K18: I
A19: Professor AUXILIAR | B19: NS | C19: 34 | D19: 6397.19 | E19: 7356.77 | F19: 13753.96 | G19: 1782.62 | H19: 1000 | I19: - | J19: 16536.58 | K19: 148829.22 | L19: 10315.47 | M19: 0 | N19: 1093.44 | O19: 160238.13 | P19: 5448096.4
A20: TOTAL | D20: 6397.19 | E20: 7356.77 | F20: 13753.96 | G20: 1782.62 | H20: 1000 | I20: - | J20: 16536.58 | K20: 148829.22 | L20: 10315.47 | M20: 0 | N20: 1093.44 | O20: 160238.13 | P20: 5448096.4
A22: PREVISÃO ORÇAMENTÁRIA 2026 (ABR A DEZ)
A24: PROFISSIONAIS | B24: NÍVEL | C24: QTD | D24: VENC BÁSICO | E24: GDPGPE | F24: REMUN INDIV | G24: ENC. SOCIAIS/A | H24: AUX ALIM | I24: AUX TRANS | J24: CUSTO MENSAL | K24: CUSTO 09 MESES | L24: GRAT. NATALINA | M24: AD. FÉRIAS | N24: ENC. SOCIAIS/B | O24: CUSTO ANUAL INDIV | P24: CUSTO ANUAL TOTAL
C25: A | D25: B | E25: C | F25: (B+C) D | G25: E | H25: F | I25: G | J25: (D+E+F+G) | K25: (H*09) | L25: (D) J | M25: (D/3) K | N25: L | O25: (I+J+K+L) M | P25: (A*M) N
J26: H
A27: Advogado | B27: NS | C27: 2 | D27: 2769.57 | E27: 4390.3 | F27: 7159.87 | G27: 821.15 | H27: 1000 | I27: - | J27: 8981.02 | K27: 80829.18 | L27: 5369.68 | M27: 0 | N27: 570.57 | O27: 86769.43 | P27: 173538.86
A28: TOTAL | D28: 2769.57 | E28: 4390.3 | F28: 7159.87 | G28: 821.15 | H28: 1000 | I28: - | J28: 8981.02 | K28: 80829.18 | L28: 5369.68 | M28: 0 | N28: 570.57 | O28: 86769.43 | P28: 173538.86
A29: PROFISSIONAIS | B29: NÍVEL | C29: QTD | D29: VENC BÁSICO | E29: GDPGPE | F29: REMUN INDIV | G29: ENC. SOCIAIS/A | H29: AUX ALIM | I29: AUX TRANS | J29: CUSTO MENSAL | K29: CUSTO 09 MESES | L29: GRAT. NATALINA | M29: AD. FÉRIAS | N29: ENC. SOCIAIS/B | O29: CUSTO ANUAL INDIV | P29: CUSTO ANUAL TOTAL
C30: A | D30: B | E30: C | F30: (B+C) D | G30: E | H30: F | I30: G | J30: (D+E+F+G) | K30: (H*09) | L30: (D) J | M30: (D/3) K | N30: L | O30: (I+J+K+L) M | P30: (A*M) N
J31: H
A32: Contador | B32: NS | C32: 2 | D32: 2769.57 | E32: 4390.3 | F32: 7159.87 | G32: 821.15 | H32: 1000 | I32: - | J32: 8981.02 | K32: 80829.18 | L32: 5369.68 | M32: 0 | N32: 570.57 | O32: 86769.43 | P32: 173538.86
A33: TOTAL | D33: 2769.57 | E33: 4390.3 | F33: 7159.87 | G33: 821.15 | H33: 1000 | I33: - | J33: 8981.02 | K33: 80829.18 | L33: 5369.68 | M33: 0 | N33: 570.57 | O33: 86769.43 | P33: 173538.86
A34: PROFISSIONAIS | B34: NÍVEL | C34: QTD | D34: VENC BÁSICO | E34: GDPGPE | F34: REMUN INDIV | G34: ENC. SOCIAIS/A | H34: AUX ALIM | I34: AUX TRANS | J34: CUSTO MENSAL | K34: CUSTO 09 MESES | L34: GRAT. NATALINA | M34: AD. FÉRIAS | N34: ENC. SOCIAIS/B | O34: CUSTO ANUAL INDIV | P34: CUSTO ANUAL TOTAL
C35: A | D35: B | E35: C | F35: (B+C) D | G35: E | H35: F | I35: G | J35: (D+E+F+G) | K35: (H*09) | L35: (D) J | M35: (D/3) K | N35: L | O35: (I+J+K+L) M | P35: (A*M) N
J36: H
A37: Pedagogo | B37: NS | C37: 1 | D37: 2769.57 | E37: 4390.3 | F37: 7159.87 | G37: 821.15 | H37: 1000 | I37: - | J37: 8981.02 | K37: 80829.18 | L37: 5369.68 | M37: 0 | N37: 570.57 | O37: 86769.43 | P37: 86769.43
A38: TOTAL | D38: 2769.57 | E38: 4390.3 | F38: 7159.87 | G38: 821.15 | H38: 1000 | I38: - | J38: 8981.02 | K38: 80829.18 | L38: 5369.68 | M38: 0 | N38: 570.57 | O38: 86769.43 | P38: 86769.43
A41: PREVISÃO ORÇAMENTÁRIA 2026 (ABR A DEZ)
A43: PROFISSIONAIS | B43: NÍVEL | C43: QTD | D43: VENC BÁSICO | E43: GDPGPE | F43: REMUN INDIV | G43: ENC. SOCIAIS/A | H43: AUX ALIM | I43: AUX TRANS | J43: CUSTO MENSAL | K43: CUSTO 09 MESES | L43: GRAT. NATALINA | M43: AD. FÉRIAS | N43: ENC. SOCIAIS/B | O43: CUSTO ANUAL INDIV | P43: CUSTO ANUAL TOTAL
C44: A | D44: B | E44: C | F44: (B+C) D | G44: E | H44: F | I44: G | J44: (D+E+F+G) | K44: (H*09) | L44: (D) J | M44: (D/3) K | N44: L | O44: (I+J+K+L) M | P44: (A*M) N
J45: H
A46: Administrador | B46: NS | C46: 1 | D46: 2769.57 | E46: 4390.3 | F46: 7159.87 | G46: 821.15 | H46: 1000 | I46: - | J46: 8981.02 | K46: 80829.18 | L46: 5369.68 | M46: 0 | N46: 570.57 | O46: 86769.43 | P46: 86769.43
...

Sheet PERFIL
A1: OM | B1: CARGOS | C1: NÍVEL | D1: ATIVIDADE | E1: REQUESITOS | F1: REMUNERAÇÃO INDIVIDUAL | G1: QTD
A2: AFA | B2: Advogado | C2: NS | D2: Planejar, direcionar, coordenar e supervisionar os trabalhos relativos ao setor da Assessoria Jurídica, no que se refere às demandas jurídicas internas e externas e aos respectivos despachos junto ao CEMAER. Tratar dos assuntos relativos ao Direito Internacional dos Conflitos Armados (DICA) e do Direito Espacial, do COMAER. | E2: Graduação em Direito, com pós-graduação em latu-sensu em Direito, emitidos por instituição reconhecida pelo MEC. Registro profissional na OAB. Experiência jurídica, mínima, de 3 anos. | F2: =INDEX(CUSTO!$F$4:$F$38,MATCH(Tabela3[[#This Row],[CARGOS]],CUSTO!$A$4:$A$38,0)) -> 7159.57 | G2: 2
A3: AFA | B3: Agente Administrativo | C3: NI | D3: Fornecer suporte administrativo nas áreas de administração, recursos humanos, financeiro, logística. Gestão de documentos, organização de arquivos, atendimento ao público, controle de estoque, gestão de contas, organização de agendas, expedição de documentos e certidões, protocolo e arquivamento de processos, gerenciamento de rotinas de compras e licitações. | E3: Possuir diploma, devidamente registrado, de curso nível médio ou técnico, em administração, recursos humanos ou outro equivalente, reconhecido pelo Ministério da Educação, Secretarias ou Conselhos Estaduais de Educação. | F3: =INDEX(CUSTO!$F$4:$F$38,MATCH(Tabela3[[#This Row],[CARGOS]],CUSTO!$A$4:$A$38,0)) -> 4787.59 | G3: 31
A4: AFA | B4: Bibliotecário | C4: NS | D4: Organizar, gerenciar e facilitar o acesso à informação em bibliotecas e centros de documentação. Exercer atividades de catalogação, classificação e indexação de livros, revistas, periódicos, documentos digitais e outros tipos de materiais, garantindo que os usuários possam encontrar as informações de forma rápida e eficiente. | E4: Possuir diploma de graduação em Biblioteconomia, devidamente registrado, reconhecido ou revalidado pelo MEC. | F4: =INDEX(CUSTO!$F$4:$F$38,MATCH(Tabela3[[#This Row],[CARGOS]],CUSTO!$A$4:$A$38,0)) -> 7159.57 | G4: 1
A5: AFA | B5: Contador | C5: NS | D5: Preparar demonstrativos, responder a relatórios e pedidos solicitados pelos órgãos de controle interno e externo; providenciar a emissão de Notas de Empenho no SIAFI e no SIASG, para os recursos creditícios, conforme autorização do Ordenador de Despesas; montar planilhas comparativas referentes aos pregões ou às cotações eletrônicas; efetuar os pagamentos das despesas realizadas, à vista de documentos hábeis, devidamente processados por quem de direito. | E5: Graduação em Ciências Contábeis, reconhecido pelo MEC, Secretarias ou Conselhos Estaduais. Registro no respectivo Conselho da Classe. | F5: =INDEX(CUSTO!$F$4:$F$38,MATCH(Tabela3[[#This Row],[CARGOS]],CUSTO!$A$4:$A$38,0)) -> 7159.57 | G5: 2
A6: AFA | B6: Professor da Carreira do Magistério Superior | C6: NS | D6: Docência em Economia. | E6: Possuir diploma, devidamente registrado, reconhecido ou revalidado pelo MEC, de conclusão de curso superior em Economia e pós-graduação stricto sensu, nível doutorado, em Economia ou Ciências Sociais ou Ciências Humanas, devidamente registrado, reconhecido ou revalidado pelo MEC. | F6: =INDEX(CUSTO!$F$4:$F$38,MATCH(Tabela3[[#This Row],[CARGOS]],CUSTO!$A$4:$A$38,0)) -> 13753.96 | G6: 1
A7: AFA | B7: Professor da Carreira do Magistério Superior | C7: NS | D7: Docência em Tecnologia da Informação, Sistemas de Informação, Cibernética. | E7: Possuir diploma, devidamente registrado, reconhecido ou revalidado pelo MEC, de conclusão de curso superior em Ciências da Computação ou em Sistemas de Informação ou em Engenharia de Computação e diploma de pós-graduação stricto sensu, nível de doutorado, em Ciências da Computação ou em Sistemas de Informação ou em Engenharia de Computação ou em áreas afins, devidamente registrado, reconhecido ou revalidado pelo MEC. | F7: =INDEX(CUSTO!$F$4:$F$38,MATCH(Tabela3[[#This Row],[CARGOS]],CUSTO!$A$4:$A$38,0)) -> 13753.96 | G7: 2
A8: AFA | B8: Professor da Carreira do Magistério Superior | C8: NS | D8: Docência em Mecânica Geral e Aerodinâmica. | E8: Possuir diploma, devidamente registrado, reconhecido ou revalidado pelo MEC, de conclusão de curso superior em licenciatura ou bacharelado em Física ou em Engenharia Aeronáutica ou em Engenharia Mecânica, e diploma de pós-graduação stricto sensu, nível de doutorado, em Física ou Engenharia Aeronáutica ou Engenharia Mecânica, devidamente registrado, reconhecido ou revalidado pelo MEC. | F8: =INDEX(CUSTO!$F$4:$F$38,MATCH(Tabela3[[#This Row],[CARGOS]],CUSTO!$A$4:$A$38,0)) -> 13753.96 | G8: 2
A9: AFA | B9: Professor da Carreira do Magistério Superior | C9: NS | D9: Docência em Administração Geral e Gestão de Pessoas. | E9: Possuir diploma, devidamente registrado, reconhecido ou revalidado pelo MEC, de conclusão de curso superior em Administração, Engenharia de Produção ou áreas afins, ou diploma de pós-graduação stricto sensu, nível de doutorado, em Administração, Recursos Humanos ou Engenharia de Produção, devidamente registrado, reconhecido ou revalidado pelo MEC. | F9: =INDEX(CUSTO!$F$4:$F$38,MATCH(Tabela3[[#This Row],[CARGOS]],CUSTO!$A$4:$A$38,0)) -> 13753.96 | G9: 1
A10: AFA | B10: Professor da Carreira do Magistério Superior | C10: NS | D10: Docência em Administração e Orçamento Público. | E10: Possuir diploma, devidamente registrado, reconhecido ou revalidado pelo MEC, de conclusão de curso superior em Economia, Administração, Administração Pública ou Contabilidade, e diploma de pós-graduação stricto sensu, nível de doutorado, em Administração ou Administração Pública, devidamente registrado, reconhecido ou revalidado pelo MEC. | F10: =INDEX(CUSTO!$F$4:$F$38,MATCH(Tabela3[[#This Row],[CARGOS]],CUSTO!$A$4:$A$38,0)) -> 13753.96 | G10: 1
A11: AFA | B11: Professor da Carreira do Magistério Superior | C11: NS | D11: Docência em Gestão de Projetos. | E11: Possuir diploma, devidamente registrado, reconhecido ou revalidado pelo MEC, de conclusão de curso superior em Engenharia ou em Administração, e diploma de pós-graduação stricto sensu, nível de doutorado, em Engenharia ou Administração, devidamente registrado, reconhecido ou revalidado pelo MEC. | F11: =INDEX(CUSTO!$F$4:$F$38,MATCH(Tabela3[[#This Row],[CARGOS]],CUSTO!$A$4:$A$38,0)) -> 13753.96 | G11: 1
A12: AFA | B12: Professor da Carreira do Magistério Superior | C12: NS | D12: Docência em Gestão de Operações e Processos. | E12: Possuir diploma, devidamente registrado, reconhecido ou revalidado pelo MEC, de conclusão de curso superior em Engenharia ou em Administração, e diploma de pós-graduação stricto sensu, nível de doutorado, em Engenharia ou Administração, devidamente registrado, reconhecido ou revalidado pelo MEC. | F12: =INDEX(CUSTO!$F$4:$F$38,MATCH(Tabela3[[#This Row],[CARGOS]],CUSTO!$A$4:$A$38,0)) -> 13753.96 | G12: 1
A13: AFA | B13: Professor da Carreira do Magistério Superior | C13: NS | D13: Docência em Logística. | E13: Possuir diploma, devidamente registrado, reconhecido ou revalidado pelo MEC, de conclusão de curso superior em Logística, Engenharia ou Administração, e diploma de pós-graduação stricto sensu, nível de doutorado, em Logística, Engenharia ou Administração, devidamente registrado, reconhecido ou revalidado pelo MEC. | F13: =INDEX(CUSTO!$F$4:$F$38,MATCH(Tabela3[[#This Row],[CARGOS]],CUSTO!$A$4:$A$38,0)) -> 13753.96 | G13: 2
... A146: CTRB | B146: Técnico em Assuntos Educacionais | C146: NS | D146: Organizar e gerenciar os documentos de ensino e os processos educacionais. Acompanhar as demandas documentais do CTRB relativas ao ensino. Assessorar à Chefia da Divisão de Ensino relativa a todos os processos documentais que dizem respeito ao ensino. Coordenar a equipe pedagógica do CTRB. Supervisionar as práticas docentes dos professores propondo melhorias e boas práticas. Coordenar as atividades de ensino, planejamento, orientação, supervisionando e avaliando estas atividades, para assegurar a regularidade do desenvolvimento do processo educativo. Assessorar nas atividades de ensino | E146: Licenciatura Plena ou Bacharelado em Pedagogia com Especialização em Psicopedagogia, realizado em instituição reconhecida pelo MEC | F146: =INDEX(CUSTO!$F$4:$F$38,MATCH(Tabela3[[#This Row],[CARGOS]],CUSTO!$A$4:$A$38,0)) -> 7159.57 | G146: 28

Sheet PAINEL
A1: PROFISSIONAIS | B1: QTD
B2: A
C3: {=TRANSPOSE(_xlfn.UNIQUE(PERFIL!A2:A216,,))} -> AFA | D3: CBNB | E3: EPCAR | F3: ECE | G3: UNIFA | H3: EEAR | I3: CTRB | J3: 0
A4: {=_xlfn._xlws.SORT(_xlfn.UNIQUE(PERFIL!B2:B1016),,,)} -> Administrador | B4: {=SUMIFS(PERFIL!G2:G216,PERFIL!B2:B216,PAINEL!A4:A203)} -> 15 | C4: {=IF(T11="TODOS",SUMIFS(PERFIL!G2:G216,PERFIL!B2:B216,PAINEL!A4:A203,PERFIL!A2:A216,PAINEL!$C$3), IF(T11="NI",SUMIFS(PERFIL!G2:G216,PERFIL!B2:B216,PAINEL!A4:A203,PERFIL!A2:A216,PAINEL!$C$3,PERFIL!$C$2:$C$216,"NI"), IF(T11="NS",SUMIFS(PERFIL!G2:G216,PERFIL!B2:B216,PAINEL!A4:A203,PERFIL!A2:A216,PAINEL!$C$3,PERFIL!$C$2:$C$216,"NS"))))} -> 0 | D4: {=IF(T11="TODOS",SUMIFS(PERFIL!G2:G216,PERFIL!B2:B216,PAINEL!A4:A202,PERFIL!A2:A216,PAINEL!$D$3), IF(T11="NI",SUMIFS(PERFIL!G2:G216,PERFIL!B2:B216,PAINEL!A4:A202,PERFIL!A2:A216,PAINEL!$D$3,PERFIL!$C$2:$C$216,"NI"), IF(T11="NS",SUMIFS(PERFIL!G2:G216,PERFIL!B2:B216,PAINEL!A4:A202,PERFIL!A2:A216,PAINEL!$D$3,PERFIL!$C$2:$C$216,"NS"))))} -> 0 | E4: {=IF(T11="TODOS",SUMIFS(PERFIL!G2:G216,PERFIL!B2:B216,PAINEL!A4:A202,PERFIL!A2:A216,PAINEL!$E$3), IF(T11="NI",SUMIFS(PERFIL!G2:G216,PERFIL!B2:B216,PAINEL!A4:A202,PERFIL!A2:A216,PAINEL!$E$3,PERFIL!$C$2:$C$216,"NI"), IF(T11="NS",SUMIFS(PERFIL!G2:G216,PERFIL!B2:B216,PAINEL!A4:A202,PERFIL!A2:A216,PAINEL!$E$3,PERFIL!$C$2:$C$216,"NS"))))} -> 6 | F4: {=IF(T11="TODOS",SUMIFS(PERFIL!G2:G216,PERFIL!B2:B216,PAINEL!A4:A202,PERFIL!A2:A216,PAINEL!$F$3), IF(T11="NI",SUMIFS(PERFIL!G2:G216,PERFIL!B2:B216,PAINEL!A4:A202,PERFIL!A2:A216,PAINEL!$F$3,PERFIL!$C$2:$C$216,"NI"), IF(T11="NS",SUMIFS(PERFIL!G2:G216,PERFIL!B2:B216,PAINEL!A4:A202,PERFIL!A2:A216,PAINEL!$F$3,PERFIL!$C$2:$C$216,"NS"))))} -> 2 | G4: {=IF(T11="TODOS",SUMIFS(PERFIL!G2:G216,PERFIL!B2:B216,PAINEL!A4:A207,PERFIL!A2:A216,PAINEL!$G$3), IF(T11="NI",SUMIFS(PERFIL!G2:G216,PERFIL!B2:B216,PAINEL!A4:A207,PERFIL!A2:A216,PAINEL!$G$3,PERFIL!$C$2:$C$216,"NI"), IF(T11="NS",SUMIFS(PERFIL!G2:G216,PERFIL!B2:B216,PAINEL!A4:A207,PERFIL!A2:A216,PAINEL!$G$3,PERFIL!$C$2:$C$216,"NS"))))} -> 0 | H4: {=IF(T11="TODOS",SUMIFS(PERFIL!G2:G216,PERFIL!B2:B216,PAINEL!A4:A207,PERFIL!A2:A216,PAINEL!$H$3), IF(T11="NI",SUMIFS(PERFIL!G2:G216,PERFIL!B2:B216,PAINEL!A4:A207,PERFIL!A2:A216,PAINEL!$H$3,PERFIL!$C$2:$C$216,"NI"), IF(T11="NS",SUMIFS(PERFIL!G2:G216,PERFIL!B2:B216,PAINEL!A4:A207,PERFIL!A2:A216,PAINEL!$H$3,PERFIL!$C$2:$C$216,"NS"))))} -> 2 | I4: {=IF(T11="TODOS",SUMIFS(PERFIL!G2:G216,PERFIL!B2:B216,PAINEL!A4:A207,PERFIL!A2:A216,PAINEL!$I$3), IF(T11="NI",SUMIFS(PERFIL!G2:G216,PERFIL!B2:B216,PAINEL!A4:A207,PERFIL!A2:A216,PAINEL!$I$3,PERFIL!$C$2:$C$216,"NI"), IF(T11="NS",SUMIFS(PERFIL!G2:G216,PERFIL!B2:B216,PAINEL!A4:A207,PERFIL!A2:A216,PAINEL!$I$3,PERFIL!$C$2:$C$216,"NS"))))} -> 5
A5: Administrador Hospitalar | B5: 2 | C5: 0 | D5: 0 | E5: 2 | F5: 0 | G5: 0 | H5: 0 | I5: 0
A6: Advogado | B6: 4 | C6: 2 | D6: 0 | E6: 1 | F6: 0 | G6: 0 | H6: 0 | I6: 1
A7: Agente Administrativo | B7: 40 | C7: 31 | D7: 6 | E7: 0 | F7: 0 | G7: 0 | H7: 3 | I7: 0 | T7: APERTE AQUI | W7: LEGENDA
A8: Analista de Tecnologia da Informação | B8: 4 | C8: 0 | D8: 0 | E8: 2 | F8: 1 | G8: 0 | H8: 0 | I8: 1 | W8: NI SIGNFICA NÍVEL INTERMEDIÁRIO
A9: Analista Técnico Administrativo | B9: 2 | C9: 0 | D9: 2 | E9: 0 | F9: 0 | G9: 0 | H9: 0 | I9: 0 | W9: NS SIGNFICA NÍVEL SUPERIOR
A10: Arquiteto | B10: 1 | C10: 0 | D10: 0 | E10: 1 | F10: 0 | G10: 0 | H10: 0 | I10: 0 | W10: "TODOS" É O SOMATÓRIO DOS DOIS NÍVEIS ACIMA.
A11: Arquivista | B11: 3 | C11: 0 | D11: 0 | E11: 1 | F11: 0 | G11: 0 | H11: 1 | I11: 1 | P11: FILTRO DE QUANTIDADE | T11: TODOS
A12: Assistente Social | B12: 5 | C12: 0 | D12: 0 | E12: 3 | F12: 1 | G12: 0 | H12: 0 | I12: 1
A13: Auxiliar Assuntos Educacionais | B13: 6 | C13: 0 | D13: 6 | E13: 0 | F13: 0 | G13: 0 | H13: 0 | I13: 0
A14: Bibliotecário | B14: 4 | C14: 1 | D14: 0 | E14: 1 | F14: 1 | G14: 0 | H14: 0 | I14: 1 | R14: AFA | S14: EPCAR | T14: CBNB | U14: EEAR | V14: UNIFA | W14: EEAR | X14: CTRB | Y14: TOTAL
A15: Comunicação Social | B15: 3 | C15: 0 | D15: 0 | E15: 2 | F15: 0 | G15: 0 | H15: 0 | I15: 1 | R15: =SUM(C:C) -> 87 | S15: =SUM(D:D) -> 38 | T15: =SUM(E:E) -> 91 | U15: =SUM(F:F) -> 10 | V15: =SUM(G:G) -> 13 | W15: =SUM(H:H) -> 16 | X15: =SUM(I:I) -> 71 | Y15: =SUM(R15:X15) -> 326
A16: Contador | B16: 6 | C16: 2 | D16: 0 | E16: 3 | F16: 0 | G16: 0 | H16: 0 | I16: 1
A17: Enfermeiro | B17: 5 | C17: 0 | D17: 0 | E17: 4 | F17: 0 | G17: 0 | H17: 1 | I17: 0
A18: Engenheiro Civil | B18: 1 | C18: 0 | D18: 0 | E18: 1 | F18: 0 | G18: 0 | H18: 0 | I18: 0
A19: Engenheiro de Segurança do Trabalho | B19: 1 | C19: 0 | D19: 0 | E19: 1 | F19: 0 | G19: 0 | H19: 0 | I19: 0
A20: Engenheiro Eletricista | B20: 1 | C20: 0 | D20: 0 | E20: 1 | F20: 0 | G20: 0 | H20: 0 | I20: 0
A21: Estatístico | B21: 3 | C21: 0 | D21: 0 | E21: 2 | F21: 0 | G21: 0 | H21: 0 | I21: 1
A22: Farmacêutico Bioquímico | B22: 2 | C22: 0 | D22: 0 | E22: 2 | F22: 0 | G22: 0 | H22: 0 | I22: 0
A23: Fisioterapeuta | B23: 3 | C23: 0 | D23: 0 | E23: 2 | F23: 0 | G23: 0 | H23: 1 | I23: 0
A24: Fonoaudiólogo | B24: 2 | C24: 0 | D24: 0 | E24: 1 | F24: 0 | G24: 0 | H24: 1 | I24: 0
A25: Médico (20h) | B25: 9 | C25: 6 | D25: 0 | E25: 2 | F25: 0 | G25: 0 | H25: 1 | I25: 0
A26: Médico do Trabalho | B26: 1 | C26: 0 | D26: 0 | E26: 1 | F26: 0 | G26: 0 | H26: 0 | I26: 0
A27: Nutricionista | B27: 4 | C27: 0 | D27: 0 | E27: 2 | F27: 0 | G27: 0 | H27: 0 | I27: 2
... A38: Terapeuta Ocupacional | B38: 3 | C38: 1 | D38: 0 | E38: 1 | F38: 0 | G38: 0 | H38: 1 | I38: 0
A39: 0 | B39: 0 | C39: 0 | D39: 0 | E39: 0 | F39: 0 | G39: 0 | H39: 0 | I39: 0
B40: 0 | C40: 0 | D40: 0 | E40: 0 | F40: 0 | G40: 0 | H40: 0 | I40: 0
B41: 0 | C41: 0 | D41: 0 | E41: 0 | F41: 0 | G41: 0 | H41: 0 | I41: 0
B42: 0 | C42: 0 | D42: 0 | E42: 0 | F42: 0 | G42: 0 | H42: 0 | I42: 0
B43: 0 | C43: 0 | D43: 0 | E43: 0 | F43: 0 | G43: 0 | H43: 0 | I43: 0
B44: 0 | C44: 0 | D44: 0 | E44: 0 | F44: 0 | G44: 0 | H44: 0 | I44: 0
B45: 0 | C45: 0 | D45: 0 | E45: 0 | F45: 0 | G45: 0 | H45: 0 | I45: 0
B46: 0 | C46: 0 | D46: 0 | E46: 0 | F46: 0 | G46: 0 | H46: 0 | I46: 0
B47: 0 | C47: 0 | D47: 0 | E47: 0 | F47: 0 | G47: 0 | H47: 0 | I47: 0
B48: 0 | C48: 0 | D48: 0 | E48: 0 | F48: 0 | G48: 0 | H48: 0 | I48: 0
B49: 0 | C49: 0 | D49: 0 | E49: 0 | F49: 0 | G49: 0 | H49: 0 | I49: 0
B50: 0 | C50: 0 | D50: 0 | E50: 0 | F50: 0 | G50: 0 | H50: 0 | I50: 0
...

Sheet CUSTO
A1: PROFISSIONAIS | B1: NÍVEL | C1: QTD | D1: VENC BÁSICO | E1: GDPGPE | F1: REMUN INDIV | G1: ENC. SOCIAIS/A | H1: AUX ALIM | I1: AUX TRANS | J1: CUSTO MENSAL | K1: CUSTO 12 MESES | L1: GRAT. NATALINA | M1: AD. FÉRIAS | N1: ENC. SOCIAIS/B | O1: CUSTO ANUAL INDIV | P1: CUSTO ANUAL TOTAL | Q1: VALOR CONFERIDO | R1: ENCARGOS SOCIAS A | U1: ENCARGOS SOCIAS B | X1: ENCARGOS SOCIAS B | AA1: ENCARGOS SOCIAS B
C2: A | D2: B | E2: C | F2: (B+C) D | G2: E | H2: F | I2: G | J2: (D+E+F+G) | K2: (H*12) | L2: (D) J | M2: (D/3) K | N2: L | O2: (I+J+K+L) M | P2: (A*M) N | R2: (E) | S2: INSS | T2: IMPACTO | U2: (J) | V2: INSS | W2: IMPACTO | X2: (K) | Y2: INSS | Z2: IMPACTO | AA2: IMPACTO TOTAL
J3: H | K3: I
A4: Administrador | B4: =INDEX(PERFIL!$C$2:$C$146,MATCH(CUSTO!A4,PERFIL!$B$2:$B$146,0)) -> NS | C4: =INDEX(PAINEL!$B$4:$B$100,MATCH($A4,PAINEL!$A$4:$A$100,0)) -> 15 | D4: 2769.57 | E4: 4390 | F4: =D4+E4 -> 7159.57 | G4: =T4 -> 821.1542 | H4: 1175 | J4: =SUM(F4:I4) -> 9155.7242 | K4: =J4*12 -> 109868.69 | L4: =F4 -> 7159.57 | M4: =F4/3 -> 2386.5233 | N4: =AA4 -> 1014.7604 | O4: =SUM(K4:N4) -> 120429.54 | P4: =C4*O4 -> 1806443.2 | Q4: CONFERIDO | R4: =F4 -> 7159.57 | S4: =IF(R4<1412.01,(105.9),IF(R4<2666.69,(((R4-1412.01)*9%)+105.9),IF(R4<4000.04,(((R4-2666.69)*12%)+218.82),IF(R4<7786.03,(((R4-4000.04)*14%)+378.82),IF(R4<13333.49,(((R4-7786.03)*14.5%)+908.86),IF(R4<26666.95,(((R4-13333.49)*16.5%)+1713.24),IF(R4<52000.54,(((R4-26666.95)*19%)+3913.26),IF(R4>52000.54,(((R4-52000.54)*22%)+8726.64),"ERRO")))))))) -> 821.1542 | T4: =IF(S4<7786.02,S4,((S4-7786.02)*8.5%)+7786.02) -> 821.1542 | U4: =L4 -> 7159.57 | V4: =IF(U4<1412.01,(105.9),IF(U4<2666.69,(((U4-1412.01)*9%)+105.9),IF(U4<4000.04,(((U4-2666.69)*12%)+218.82),IF(U4<7786.03,(((U4-4000.04)*14%)+378.82),IF(U4<13333.49,(((U4-7786.03)*14.5%)+908.86),IF(U4<26666.95,(((U4-13333.49)*16.5%)+1713.24),IF(U4<52000.54,(((U4-26666.95)*19%)+3913.26),IF(U4>52000.54,(((U4-52000.54)*22%)+8726.64),"ERRO")))))))) -> 821.1542 | W4: =IF(V4<7786.02,V4,((V4-7786.02)*8.5%)+7786.02) -> 821.1542 | X4: =M4 -> 2386.5233 | Y4: =IF(X4<1412.01,(105.9),IF(X4<2666.69,(((X4-1412.01)*9%)+105.9),IF(X4<4000.04,(((X4-2666.69)*12%)+218.82),IF(X4<7786.03,(((X4-4000.04)*14%)+378.82),IF(X4<13333.49,(((X4-7786.03)*14.5%)+908.86),IF(X4<26666.95,(((X4-13333.49)*16.5%)+1713.24),IF(X4<52000.54,(((X4-26666.95)*19%)+3913.26),IF(X4>52000.54,(((X4-52000.54)*22%)+8726.64),"ERRO")))))))) -> 193.6062 | Z4: =IF(Y4<7786.02,Y4,((Y4-7786.02)*8.5%)+7786.02) -> 193.6062 | AA4: =SUM(W4,Z4) -> 1014.7604
A5: Administrador Hospitalar | B5: =INDEX(PERFIL!$C$2:$C$146,MATCH(CUSTO!A5,PERFIL!$B$2:$B$146,0)) -> NS | C5: =INDEX(PAINEL!$B$4:$B$100,MATCH($A5,PAINEL!$A$4:$A$100,0)) -> 2 | D5: 2769.57 | E5: 4390 | F5: =D5+E5 -> 7159.57 | G5: =T5 -> 821.1542 | H5: 1175 | I5: - | J5: =SUM(F5:I5) -> 9155.7242 | K5: =J5*12 -> 109868.69 | L5: =F5 -> 7159.57 | M5: =F5/3 -> 2386.5233 | N5: =AA5 -> 1014.7604 | O5: =SUM(K5:N5) -> 120429.54 | P5: =C5*O5 -> 240859.09 | Q5: CONFERIDO | R5: =F5 -> 7159.57 | S5: =IF(R5<1412.01,(105.9),IF(R5<2666.69,(((R5-1412.01)*9%)+105.9),IF(R5<4000.04,(((R5-2666.69)*12%)+218.82),IF(R5<7786.03,(((R5-4000.04)*14%)+378.82),IF(R5<13333.49,(((R5-7786.03)*14.5%)+908.86),IF(R5<26666.95,(((R5-13333.49)*16.5%)+1713.24),IF(R5<52000.54,(((R5-26666.95)*19%)+3913.26),IF(R5>52000.54,(((R5-52000.54)*22%)+8726.64),"ERRO")))))))) -> 821.1542 | T5: =IF(S5<7786.02,S5,((S5-7786.02)*8.5%)+7786.02) -> 821.1542 | U5: =L5 -> 7159.57 | V5: =IF(U5<1412.01,(105.9),IF(U5<2666.69,(((U5-1412.01)*9%)+105.9),IF(U5<4000.04,(((U5-2666.69)*12%)+218.82),IF(U5<7786.03,(((U5-4000.04)*14%)+378.82),IF(U5<13333.49,(((U5-7786.03)*14.5%)+908.86),IF(U5<26666.95,(((U5-13333.49)*16.5%)+1713.24),IF(U5<52000.54,(((U5-26666.95)*19%)+3913.26),IF(U5>52000.54,(((U5-52000.54)*22%)+8726.64),"ERRO")))))))) -> 821.1542 | W5: =IF(V5<7786.02,V5,((V5-7786.02)*8.5%)+7786.02) -> 821.1542 | X5: =M5 -> 2386.5233 | Y5: =IF(X5<1412.01,(105.9),IF(X5<2666.69,(((X5-1412.01)*9%)+105.9),IF(X5<4000.04,(((X5-2666.69)*12%)+218.82),IF(X5<7786.03,(((X5-4000.04)*14%)+378.82),IF(X5<13333.49,(((X5-7786.03)*14.5%)+908.86),IF(X5<26666.95,(((X5-13333.49)*16.5%)+1713.24),IF(X5<52000.54,(((X5-26666.95)*19%)+3913.26),IF(X5>52000.54,(((X5-52000.54)*22%)+8726.64),"ERRO")))))))) -> 193.6062 | Z5: =IF(Y5<7786.02,Y5,((Y5-7786.02)*8.5%)+7786.02) -> 193.6062 | AA5: =SUM(W5,Z5) -> 1014.7604
A6: Advogado | B6: =INDEX(PERFIL!$C$2:$C$146,MATCH(CUSTO!A6,PERFIL!$B$2:$B$146,0)) -> NS | C6: =INDEX(PAINEL!$B$4:$B$100,MATCH($A6,PAINEL!$A$4:$A$100,0)) -> 4 | D6: 2769.57 | E6: 4390 | F6: =D6+E6 -> 7159.57 | G6: =T6 -> 821.1542 | H6: 1175 | I6: - | J6: =SUM(F6:I6) -> 9155.7242 | K6: =J6*12 -> 109868.69 | L6: =F6 -> 7159.57 | M6: =F6/3 -> 2386.5233 | N6: =AA6 -> 1014.7604 | O6: =SUM(K6:N6) -> 120429.54 | P6: =C6*O6 -> 481718.18 | Q6: CONFERIDO | R6: =F6 -> 7159.57 | S6: =IF(R6<1412.01,(105.9),IF(R6<2666.69,(((R6-1412.01)*9%)+105.9),IF(R6<4000.04,(((R6-2666.69)*12%)+218.82),IF(R6<7786.03,(((R6-4000.04)*14%)+378.82),IF(R6<13333.49,(((R6-7786.03)*14.5%)+908.86),IF(R6<26666.95,(((R6-13333.49)*16.5%)+1713.24),IF(R6<52000.54,(((R6-26666.95)*19%)+3913.26),IF(R6>52000.54,(((R6-52000.54)*22%)+8726.64),"ERRO")))))))) -> 821.1542 | T6: =IF(S6<7786.02,S6,((S6-7786.02)*8.5%)+7786.02) -> 821.1542 | U6: =L6 -> 7159.57 | V6: =IF(U6<1412.01,(105.9),IF(U6<2666.69,(((U6-1412.01)*9%)+105.9),IF(U6<4000.04,(((U6-2666.69)*12%)+218.82),IF(U6<7786.03,(((U6-4000.04)*14%)+378.82),IF(U6<13333.49,(((U6-7786.03)*14.5%)+908.86),IF(U6<26666.95,(((U6-13333.49)*16.5%)+1713.24),IF(U6<52000.54,(((U6-26666.95)*19%)+3913.26),IF(U6>52000.54,(((U6-52000.54)*22%)+8726.64),"ERRO")))))))) -> 821.1542 | W6: =IF(V6<7786.02,V6,((V6-7786.02)*8.5%)+7786.02) -> 821.1542 | X6: =M6 -> 2386.5233 | Y6: =IF(X6<1412.01,(105.9),IF(X6<2666.69,(((X6-1412.01)*9%)+105.9),IF(X6<4000.04,(((X6-2666.69)*12%)+218.82),IF(X6<7786.03,(((X6-4000.04)*14%)+378.82),IF(X6<13333.49,(((X6-7786.03)*14.5%)+908.86),IF(X6<26666.95,(((X6-13333.49)*16.5%)+1713.24),IF(X6<52000.54,(((X6-26666.95)*19%)+3913.26),IF(X6>52000.54,(((X6-52000.54)*22%)+8726.64),"ERRO")))))))) -> 193.6062 | Z6: =IF(Y6<7786.02,Y6,((Y6-7786.02)*8.5%)+7786.02) -> 193.6062 | AA6: =SUM(W6,Z6) -> 1014.7604
A7: Agente Administrativo | B7: =INDEX(PERFIL!$C$2:$C$146,MATCH(CUSTO!A7,PERFIL!$B$2:$B$146,0)) -> NI | C7: =INDEX(PAINEL!$B$4:$B$100,MATCH($A7,PAINEL!$A$4:$A$100,0)) -> 40 | D7: 2182.59 | E7: 2605 | F7: =D7+E7 -> 4787.59 | G7: =T7 -> 489.077 | H7: 1175 | I7: - | J7: =SUM(F7:I7) -> 6451.667 | K7: =J7*12 -> 77420.004 | L7: =F7 -> 4787.59 | M7: =F7/3 -> 1595.8633 | N7: =AA7 -> 611.5238 | O7: =SUM(K7:N7) -> 84414.981 | P7: =C7*O7 -> 3376599.2 | Q7: CONFERIDO | R7: =F7 -> 4787.59 | S7: =IF(R7<1412.01,(105.9),IF(R7<2666.69,(((R7-1412.01)*9%)+105.9),IF(R7<4000.04,(((R7-2666.69)*12%)+218.82),IF(R7<7786.03,(((R7-4000.04)*14%)+378.82),IF(R7<13333.49,(((R7-7786.03)*14.5%)+908.86),IF(R7<26666.95,(((R7-13333.49)*16.5%)+1713.24),IF(R7<52000.54,(((R7-26666.95)*19%)+3913.26),IF(R7>52000.54,(((R7-52000.54)*22%)+8726.64),"ERRO")))))))) -> 489.077 | T7: =IF(S7<7786.02,S7,((S7-7786.02)*8.5%)+7786.02) -> 489.077 | U7: =L7 -> 4787.59 | V7: =IF(U7<1412.01,(105.9),IF(U7<2666.69,(((U7-1412.01)*9%)+105.9),IF(U7<4000.04,(((U7-2666.69)*12%)+218.82),IF(U7<7786.03,(((U7-4000.04)*14%)+378.82),IF(U7<13333.49,(((U7-7786.03)*14.5%)+908.86),IF(U7<26666.95,(((U7-13333.49)*16.5%)+1713.24),IF(U7<52000.54,(((U7-26666.95)*19%)+3913.26),IF(U7>52000.54,(((U7-52000.54)*22%)+8726.64),"ERRO")))))))) -> 489.077 | W7: =IF(V7<7786.02,V7,((V7-7786.02)*8.5%)+7786.02) -> 489.077 | X7: =M7 -> 1595.8633 | Y7: =IF(X7<1412.01,(105.9),IF(X7<2666.69,(((X7-1412.01)*9%)+105.9),IF(X7<4000.04,(((X7-2666.69)*12%)+218.82),IF(X7<7786.03,(((X7-4000.04)*14%)+378.82),IF(X7<13333.49,(((X7-7786.03)*14.5%)+908.86),IF(X7<26666.95,(((X7-13333.49)*16.5%)+1713.24),IF(X7<52000.54,(((X7-26666.95)*19%)+3913.26),IF(X7>52000.54,(((X7-52000.54)*22%)+8726.64),"ERRO")))))))) -> 122.4468 | Z7: =IF(Y7<7786.02,Y7,((Y7-7786.02)*8.5%)+7786.02) -> 122.4468 | AA7: =SUM(W7,Z7) -> 611.5238
A8: Analista de Tecnologia da Informação | B8: =INDEX(PERFIL!$C$2:$C$146,MATCH(CUSTO!A8,PERFIL!$B$2:$B$146,0)) -> NS | C8: =INDEX(PAINEL!$B$4:$B$100,MATCH($A8,PAINEL!$A$4:$A$100,0)) -> 4 | D8: 2769.57 | E8: 4390 | F8: =D8+E8 -> 7159.57 | G8: =T8 -> 821.1542 | H8: 1175 | I8: - | J8: =SUM(F8:I8) -> 9155.7242 | K8: =J8*12 -> 109868.69 | L8: =F8 -> 7159.57 | M8: =F8/3 -> 2386.5233 | N8: =AA8 -> 1014.7604 | O8: =SUM(K8:N8) -> 120429.54 | P8: =C8*O8 -> 481718.18 | Q8: CONFERIDO | R8: =F8 -> 7159.57 | S8: =IF(R8<1412.01,(105.9),IF(R8<2666.69,(((R8-1412.01)*9%)+105.9),IF(R8<4000.04,(((R8-2666.69)*12%)+218.82),IF(R8<7786.03,(((R8-4000.04)*14%)+378.82),IF(R8<13333.49,(((R8-7786.03)*14.5%)+908.86),IF(R8<26666.95,(((R8-13333.49)*16.5%)+1713.24),IF(R8<52000.54,(((R8-26666.95)*19%)+3913.26),IF(R8>52000.54,(((R8-52000.54)*22%)+8726.64),"ERRO")))))))) -> 821.1542 | T8: =IF(S8<7786.02,S8,((S8-7786.02)*8.5%)+7786.02) -> 821.1542 | U8: =L8 -> 7159.57 | V8: =IF(U8<1412.01,(105.9),IF(U8<2666.69,(((U8-1412.01)*9%)+105.9),IF(U8<4000.04,(((U8-2666.69)*12%)+218.82),IF(U8<7786.03,(((U8-4000.04)*14%)+378.82),IF(U8<13333.49,(((U8-7786.03)*14.5%)+908.86),IF(U8<26666.95,(((U8-13333.49)*16.5%)+1713.24),IF(U8<52000.54,(((U8-26666.95)*19%)+3913.26),IF(U8>52000.54,(((U8-52000.54)*22%)+8726.64),"ERRO")))))))) -> 821.1542 | W8: =IF(V8<7786.02,V8,((V8-7786.02)*8.5%)+7786.02) -> 821.1542 | X8: =M8 -> 2386.5233 | Y8: =IF(X8<1412.01,(105.9),IF(X8<2666.69,(((X8-1412.01)*9%)+105.9),IF(X8<4000.04,(((X8-2666.69)*12%)+218.82),IF(X8<7786.03,(((X8-4000.04)*14%)+378.82),IF(X8<13333.49,(((X8-7786.03)*14.5%)+908.86),IF(X8<26666.95,(((X8-13333.49)*16.5%)+1713.24),IF(X8<52000.54,(((X8-26666.95)*19%)+3913.26),IF(X8>52000.54,(((X8-52000.54)*22%)+8726.64),"ERRO")))))))) -> 193.6062 | Z8: =IF(Y8<7786.02,Y8,((Y8-7786.02)*8.5%)+7786.02) -> 193.6062 | AA8: =SUM(W8,Z8) -> 1014.7604
A9: Analista Técnico Administrativo | B9: =INDEX(PERFIL!$C$2:$C$146,MATCH(CUSTO!A9,PERFIL!$B$2:$B$146,0)) -> NS | C9: =INDEX(PAINEL!$B$4:$B$100,MATCH($A9,PAINEL!$A$4:$A$100,0)) -> 2 | D9: 2769.57 | E9: 4390 | F9: =D9+E9 -> 7159.57 | G9: =T9 -> 821.1542 | H9: 1175 | I9: - | J9: =SUM(F9:I9) -> 9155.7242 | K9: =J9*12 -> 109868.69 | L9: =F9 -> 7159.57 | M9: =F9/3 -> 2386.5233 | N9: =AA9 -> 1014.7604 | O9: =SUM(K9:N9) -> 120429.54 | P9: =C9*O9 -> 240859.09 | Q9: CONFERIDO | R9: =F9 -> 7159.57 | S9: =IF(R9<1412.01,(105.9),IF(R9<2666.69,(((R9-1412.01)*9%)+105.9),IF(R9<4000.04,(((R9-2666.69)*12%)+218.82),IF(R9<7786.03,(((R9-4000.04)*14%)+378.82),IF(R9<13333.49,(((R9-7786.03)*14.5%)+908.86),IF(R9<26666.95,(((R9-13333.49)*16.5%)+1713.24),IF(R9<52000.54,(((R9-26666.95)*19%)+3913.26),IF(R9>52000.54,(((R9-52000.54)*22%)+8726.64),"ERRO")))))))) -> 821.1542 | T9: =IF(S9<7786.02,S9,((S9-7786.02)*8.5%)+7786.02) -> 821.1542 | U9: =L9 -> 7159.57 | V9: =IF(U9<1412.01,(105.9),IF(U9<2666.69,(((U9-1412.01)*9%)+105.9),IF(U9<4000.04,(((U9-2666.69)*12%)+218.82),IF(U9<7786.03,(((U9-4000.04)*14%)+378.82),IF(U9<13333.49,(((U9-7786.03)*14.5%)+908.86),IF(U9<26666.95,(((U9-13333.49)*16.5%)+1713.24),IF(U9<52000.54,(((U9-26666.95)*19%)+3913.26),IF(U9>52000.54,(((U9-52000.54)*22%)+8726.64),"ERRO")))))))) -> 821.1542 | W9: =IF(V9<7786.02,V9,((V9-7786.02)*8.5%)+7786.02) -> 821.1542 | X9: =M9 -> 2386.5233 | Y9: =IF(X9<1412.01,(105.9),IF(X9<2666.69,(((X9-1412.01)*9%)+105.9),IF(X9<4000.04,(((X9-2666.69)*12%)+218.82),IF(X9<7786.03,(((X9-4000.04)*14%)+378.82),IF(X9<13333.49,(((X9-7786.03)*14.5%)+908.86),IF(X9<26666.95,(((X9-13333.49)*16.5%)+1713.24),IF(X9<52000.54,(((X9-26666.95)*19%)+3913.26),IF(X9>52000.54,(((X9-52000.54)*22%)+8726.64),"ERRO")))))))) -> 193.6062 | Z9: =IF(Y9<7786.02,Y9,((Y9-7786.02)*8.5%)+7786.02) -> 193.6062 | AA9: =SUM(W9,Z9) -> 1014.7604
A10: Arquiteto | B10: =INDEX(PERFIL!$C$2:$C$146,MATCH(CUSTO!A10,PERFIL!$B$2:$B$146,0)) -> NS | C10: =INDEX(PAINEL!$B$4:$B$100,MATCH($A10,PAINEL!$A$4:$A$100,0)) -> 1 | D10: 3755.5 | E10: 6641 | F10: =D10+E10 -> 10396.5 | G10: =T10 -> 1287.3782 | H10: 1175 | I10: - | J10: =SUM(F10:I10) -> 12858.878 | K10: =J10*12 -> 154306.54 | L10: =F10 -> 10396.5 | M10: =F10/3 -> 3465.5 | N10: =AA10 -> 1602.0554 | O10: =SUM(K10:N10) -> 169770.59 | P10: =C10*O10 -> 169770.59 | Q10: CONFERIDO | R10: =F10 -> 10396.5 | S10: =IF(R10<1412.01,(105.9),IF(R10<2666.69,(((R10-1412.01)*9%)+105.9),IF(R10<4000.04,(((R10-2666.69)*12%)+218.82),IF(R10<7786.03,(((R10-4000.04)*14%)+378.82),IF(R10<13333.49,(((R10-7786.03)*14.5%)+908.86),IF(R10<26666.95,(((R10-13333.49)*16.5%)+1713.24),IF(R10<52000.54,(((R10-26666.95)*19%)+3913.26),IF(R10>52000.54,(((R10-52000.54)*22%)+8726.64),"ERRO")))))))) -> 1287.3782 | T10: =IF(S10<7786.02,S10,((S10-7786.02)*8.5%)+7786.02) -> 1287.3782 | U10: =L10 -> 10396.5 | V10: =IF(U10<1412.01,(105.9),IF(U10<2666.69,(((U10-1412.01)*9%)+105.9),IF(U10<4000.04,(((U10-2666.69)*12%)+218.82),IF(U10<7786.03,(((U10-4000.04)*14%)+378.82),IF(U10<13333.49,(((U10-7786.03)*14.5%)+908.86),IF(U10<26666.95,(((U10-13333.49)*16.5%)+1713.24),IF(U10<52000.54,(((U10-26666.95)*19%)+3913.26),IF(U10>52000.54,(((U10-52000.54)*22%)+8726.64),"ERRO")))))))) -> 1287.3782 | W10: =IF(V10<7786.02,V10,((V10-7786.02)*8.5%)+7786.02) -> 1287.3782 | X10: =M10 -> 3465.5 | Y10: =IF(X10<1412.01,(105.9),IF(X10<2666.69,(((X10-1412.01)*9%)+105.9),IF(X10<4000.04,(((X10-2666.69)*12%)+218.82),IF(X10<7786.03,(((X10-4000.04)*14%)+378.82),IF(X10<13333.49,(((X10-7786.03)*14.5%)+908.86),IF(X10<26666.95,(((X10-13333.49)*16.5%)+1713.24),IF(X10<52000.54,(((X10-26666.95)*19%)+3913.26),IF(X10>52000.54,(((X10-52000.54)*22%)+8726.64),"ERRO")))))))) -> 314.6772 | Z10: =IF(Y10<7786.02,Y10,((Y10-7786.02)*8.5%)+7786.02) -> 314.6772 | AA10: =SUM(W10,Z10) -> 1602.0554
A11: Arquivista | B11: =INDEX(PERFIL!$C$2:$C$146,MATCH(CUSTO!A11,PERFIL!$B$2:$B$146,0)) -> NS | C11: =INDEX(PAINEL!$B$4:$B$100,MATCH($A11,PAINEL!$A$4:$A$100,0)) -> 3 | D11: 2769.57 | E11: 4390 | F11: =D11+E11 -> 7159.57 | G11: =T11 -> 821.1542 | H11: 1175 | I11: - | J11: =SUM(F11:I11) -> 9155.7242 | K11: =J11*12 -> 109868.69 | L11: =F11 -> 7159.57 | M11: =F11/3 -> 2386.5233 | N11: =AA11 -> 1014.7604 | O11: =SUM(K11:N11) -> 120429.54 | P11: =C11*O11 -> 361288.63 | Q11: CONFERIDO | R11: =F11 -> 7159.57 | S11: =IF(R11<1412.01,(105.9),IF(R11<2666.69,(((R11-1412.01)*9%)+105.9),IF(R11<4000.04,(((R11-2666.69)*12%)+218.82),IF(R11<7786.03,(((R11-4000.04)*14%)+378.82),IF(R11<13333.49,(((R11-7786.03)*14.5%)+908.86),IF(R11<26666.95,(((R11-13333.49)*16.5%)+1713.24),IF(R11<52000.54,(((R11-26666.95)*19%)+3913.26),IF(R11>52000.54,(((R11-52000.54)*22%)+8726.64),"ERRO")))))))) -> 821.1542 | T11: =IF(S11<7786.02,S11,((S11-7786.02)*8.5%)+7786.02) -> 821.1542 | U11: =L11 -> 7159.57 | V11: =IF(U11<1412.01,(105.9),IF(U11<2666.69,(((U11-1412.01)*9%)+105.9),IF(U11<4000.04,(((U11-2666.69)*12%)+218.82),IF(U11<7786.03,(((U11-4000.04)*14%)+378.82),IF(U11<13333.49,(((U11-7786.03)*14.5%)+908.86),IF(U11<26666.95,(((U11-13333.49)*16.5%)+1713.24),IF(U11<52000.54,(((U11-26666.95)*19%)+3913.26),IF(U11>52000.54,(((U11-52000.54)*22%)+8726.64),"ERRO")))))))) -> 821.1542 | W11: =IF(V11<7786.02,V11,((V11-7786.02)*8.5%)+7786.02) -> 821.1542 | X11: =M11 -> 2386.5233 | Y11: =IF(X11<1412.01,(105.9),IF(X11<2666.69,(((X11-1412.01)*9%)+105.9),IF(X11<4000.04,(((X11-2666.69)*12%)+218.82),IF(X11<7786.03,(((X11-4000.04)*14%)+378.82),IF(X11<13333.49,(((X11-7786.03)*14.5%)+908.86),IF(X11<26666.95,(((X11-13333.49)*16.5%)+1713.24),IF(X11<52000.54,(((X11-26666.95)*19%)+3913.26),IF(X11>52000.54,(((X11-52000.54)*22%)+8726.64),"ERRO")))))))) -> 193.6062 | Z11: =IF(Y11<7786.02,Y11,((Y11-7786.02)*8.5%)+7786.02) -> 193.6062 | AA11: =SUM(W11,Z11) -> 1014.7604
A12: Assistente Social | B12: =INDEX(PERFIL!$C$2:$C$146,MATCH(CUSTO!A12,PERFIL!$B$2:$B$146,0)) -> NS | C12: =INDEX(PAINEL!$B$4:$B$100,MATCH($A12,PAINEL!$A$4:$A$100,0)) -> 5 | D12: 2769.57 | E12: 4390 | F12: =D12+E12 -> 7159.57 | G12: =T12 -> 821.1542 | H12: 1175 | I12: - | J12: =SUM(F12:I12) -> 9155.7242 | K12: =J12*12 -> 109868.69 | L12: =F12 -> 7159.57 | M12: =F12/3 -> 2386.5233 | N12: =AA12 -> 1014.7604 | O12: =SUM(K12:N12) -> 120429.54 | P12: =C12*O12 -> 602147.72 | Q12: CONFERIDO | R12: =F12 -> 7159.57 | S12: =IF(R12<1412.01,(105.9),IF(R12<2666.69,(((R12-1412.01)*9%)+105.9),IF(R12<4000.04,(((R12-2666.69)*12%)+218.82),IF(R12<7786.03,(((R12-4000.04)*14%)+378.82),IF(R12<13333.49,(((R12-7786.03)*14.5%)+908.86),IF(R12<26666.95,(((R12-13333.49)*16.5%)+1713.24),IF(R12<52000.54,(((R12-26666.95)*19%)+3913.26),IF(R12>52000.54,(((R12-52000.54)*22%)+8726.64),"ERRO")))))))) -> 821.1542 | T12: =IF(S12<7786.02,S12,((S12-7786.02)*8.5%)+7786.02) -> 821.1542 | U12: =L12 -> 7159.57 | V12: =IF(U12<1412.01,(105.9),IF(U12<2666.69,(((U12-1412.01)*9%)+105.9),IF(U12<4000.04,(((U12-2666.69)*12%)+218.82),IF(U12<7786.03,(((U12-4000.04)*14%)+378.82),IF(U12<13333.49,(((U12-7786.03)*14.5%)+908.86),IF(U12<26666.95,(((U12-13333.49)*16.5%)+1713.24),IF(U12<52000.54,(((U12-26666.95)*19%)+3913.26),IF(U12>52000.54,(((U12-52000.54)*22%)+8726.64),"ERRO")))))))) -> 821.1542 | W12: =IF(V12<7786.02,V12,((V12-7786.02)*8.5%)+7786.02) -> 821.1542 | X12: =M12 -> 2386.5233 | Y12: =IF(X12<1412.01,(105.9),IF(X12<2666.69,(((X12-1412.01)*9%)+105.9),IF(X12<4000.04,(((X12-2666.69)*12%)+218.82),IF(X12<7786.03,(((X12-4000.04)*14%)+378.82),IF(X12<13333.49,(((X12-7786.03)*14.5%)+908.86),IF(X12<26666.95,(((X12-13333.49)*16.5%)+1713.24),IF(X12<52000.54,(((X12-26666.95)*19%)+3913.26),IF(X12>52000.54,(((X12-52000.54)*22%)+8726.64),"ERRO")))))))) -> 193.6062 | Z12: =IF(Y12<7786.02,Y12,((Y12-7786.02)*8.5%)+7786.02) -> 193.6062 | AA12: =SUM(W12,Z12) -> 1014.7604
A13: Auxiliar Assuntos Educacionais | B13: =INDEX(PERFIL!$C$2:$C$146,MATCH(CUSTO!A13,PERFIL!$B$2:$B$146,0)) -> NI | C13: =INDEX(PAINEL!$B$4:$B$100,MATCH($A13,PAINEL!$A$4:$A$100,0)) -> 6 | D13: 2182.59 | E13: 2605 | F13: =D13+E13 -> 4787.59 | G13: =T13 -> 489.077 | H13: 1175 | I13: - | J13: =SUM(F13:I13) -> 6451.667 | K13: =J13*12 -> 77420.004 | L13: =F13 -> 4787.59 | M13: =F13/3 -> 1595.8633 | N13: =AA13 -> 611.5238 | O13: =SUM(K13:N13) -> 84414.981 | P13: =C13*O13 -> 506489.89 | Q13: CONFERIDO | R13: =F13 -> 4787.59 | S13: =IF(R13<1412.01,(105.9),IF(R13<2666.69,(((R13-1412.01)*9%)+105.9),IF(R13<4000.04,(((R13-2666.69)*12%)+218.82),IF(R13<7786.03,(((R13-4000.04)*14%)+378.82),IF(R13<13333.49,(((R13-7786.03)*14.5%)+908.86),IF(R13<26666.95,(((R13-13333.49)*16.5%)+1713.24),IF(R13<52000.54,(((R13-26666.95)*19%)+3913.26),IF(R13>52000.54,(((R13-52000.54)*22%)+8726.64),"ERRO")))))))) -> 489.077 | T13: =IF(S13<7786.02,S13,((S13-7786.02)*8.5%)+7786.02) -> 489.077 | U13: =L13 -> 4787.59 | V13: =IF(U13<1412.01,(105.9),IF(U13<2666.69,(((U13-1412.01)*9%)+105.9),IF(U13<4000.04,(((U13-2666.69)*12%)+218.82),IF(U13<7786.03,(((U13-4000.04)*14%)+378.82),IF(U13<13333.49,(((U13-7786.03)*14.5%)+908.86),IF(U13<26666.95,(((U13-13333.49)*16.5%)+1713.24),IF(U13<52000.54,(((U13-26666.95)*19%)+3913.26),IF(U13>52000.54,(((U13-52000.54)*22%)+8726.64),"ERRO")))))))) -> 489.077 | W13: =IF(V13<7786.02,V13,((V13-7786.02)*8.5%)+7786.02) -> 489.077 | X13: =M13 -> 1595.8633 | Y13: =IF(X13<1412.01,(105.9),IF(X13<2666.69,(((X13-1412.01)*9%)+105.9),IF(X13<4000.04,(((X13-2666.69)*12%)+218.82),IF(X13<7786.03,(((X13-4000.04)*14%)+378.82),IF(X13<13333.49,(((X13-7786.03)*14.5%)+908.86),IF(X13<26666.95,(((X13-13333.49)*16.5%)+1713.24),IF(X13<52000.54,(((X13-26666.95)*19%)+3913.26),IF(X13>52000.54,(((X13-52000.54)*22%)+8726.64),"ERRO")))))))) -> 122.4468 | Z13: =IF(Y13<7786.02,Y13,((Y13-7786.02)*8.5%)+7786.02) -> 122.4468 | AA13: =SUM(W13,Z13) -> 611.5238
A14: Bibliotecário | B14: =INDEX(PERFIL!$C$2:$C$146,MATCH(CUSTO!A14,PERFIL!$B$2:$B$146,0)) -> NS | C14: =INDEX(PAINEL!$B$4:$B$100,MATCH($A14,PAINEL!$A$4:$A$100,0)) -> 4 | D14: 2769.57 | E14: 4390 | F14: =D14+E14 -> 7159.57 | G14: =T14 -> 821.1542 | H14: 1175 | I14: - | J14: =SUM(F14:I14) -> 9155.7242 | K14: =J14*12 -> 109868.69 | L14: =F14 -> 7159.57 | M14: =F14/3 -> 2386.5233 | N14: =AA14 -> 1014.7604 | O14: =SUM(K14:N14) -> 120429.54 | P14: =C14*O14 -> 481718.18 | Q14: CONFERIDO | R14: =F14 -> 7159.57 | S14: =IF(R14<1412.01,(105.9),IF(R14<2666.69,(((R14-1412.01)*9%)+105.9),IF(R14<4000.04,(((R14-2666.69)*12%)+218.82),IF(R14<7786.03,(((R14-4000.04)*14%)+378.82),IF(R14<13333.49,(((R14-7786.03)*14.5%)+908.86),IF(R14<26666.95,(((R14-13333.49)*16.5%)+1713.24),IF(R14<52000.54,(((R14-26666.95)*19%)+3913.26),IF(R14>52000.54,(((R14-52000.54)*22%)+8726.64),"ERRO")))))))) -> 821.1542 | T14: =IF(S14<7786.02,S14,((S14-7786.02)*8.5%)+7786.02) -> 821.1542 | U14: =L14 -> 7159.57 | V14: =IF(U14<1412.01,(105.9),IF(U14<2666.69,(((U14-1412.01)*9%)+105.9),IF(U14<4000.04,(((U14-2666.69)*12%)+218.82),IF(U14<7786.03,(((U14-4000.04)*14%)+378.82),IF(U14<13333.49,(((U14-7786.03)*14.5%)+908.86),IF(U14<26666.95,(((U14-13333.49)*16.5%)+1713.24),IF(U14<52000.54,(((U14-26666.95)*19%)+3913.26),IF(U14>52000.54,(((U14-52000.54)*22%)+8726.64),"ERRO")))))))) -> 821.1542 | W14: =IF(V14<7786.02,V14,((V14-7786.02)*8.5%)+7786.02) -> 821.1542 | X14: =M14 -> 2386.5233 | Y14: =IF(X14<1412.01,(105.9),IF(X14<2666.69,(((X14-1412.01)*9%)+105.9),IF(X14<4000.04,(((X14-2666.69)*12%)+218.82),IF(X14<7786.03,(((X14-4000.04)*14%)+378.82),IF(X14<13333.49,(((X14-7786.03)*14.5%)+908.86),IF(X14<26666.95,(((X14-13333.49)*16.5%)+1713.24),IF(X14<52000.54,(((X14-26666.95)*19%)+3913.26),IF(X14>52000.54,(((X14-52000.54)*22%)+8726.64),"ERRO")))))))) -> 193.6062 | Z14: =IF(Y14<7786.02,Y14,((Y14-7786.02)*8.5%)+7786.02) -> 193.6062 | AA14: =SUM(W14,Z14) -> 1014.7604
A15: Contador | B15: =INDEX(PERFIL!$C$2:$C$146,MATCH(CUSTO!A15,PERFIL!$B$2:$B$146,0)) -> NS | C15: =INDEX(PAINEL!$B$4:$B$100,MATCH($A15,PAINEL!$A$4:$A$100,0)) -> 6 | D15: 2769.57 | E15: 4390 | F15: =D15+E15 -> 7159.57 | G15: =T15 -> 821.1542 | H15: 1175 | I15: - | J15: =SUM(F15:I15) -> 9155.7242 | K15: =J15*12 -> 109868.69 | L15: =F15 -> 7159.57 | M15: =F15/3 -> 2386.5233 | N15: =AA15 -> 1014.7604 | O15: =SUM(K15:N15) -> 120429.54 | P15: =C15*O15 -> 722577.26 | Q15: CONFERIDO | R15: =F15 -> 7159.57 | S15: =IF(R15<1412.01,(105.9),IF(R15<2666.69,(((R15-1412.01)*9%)+105.9),IF(R15<4000.04,(((R15-2666.69)*12%)+218.82),IF(R15<7786.03,(((R15-4000.04)*14%)+378.82),IF(R15<13333.49,(((R15-7786.03)*14.5%)+908.86),IF(R15<26666.95,(((R15-13333.49)*16.5%)+1713.24),IF(R15<52000.54,(((R15-26666.95)*19%)+3913.26),IF(R15>52000.54,(((R15-52000.54)*22%)+8726.64),"ERRO")))))))) -> 821.1542 | T15: =IF(S15<7786.02,S15,((S15-7786.02)*8.5%)+7786.02) -> 821.1542 | U15: =L15 -> 7159.57 | V15: =IF(U15<1412.01,(105.9),IF(U15<2666.69,(((U15-1412.01)*9%)+105.9),IF(U15<4000.04,(((U15-2666.69)*12%)+218.82),IF(U15<7786.03,(((U15-4000.04)*14%)+378.82),IF(U15<13333.49,(((U15-7786.03)*14.5%)+908.86),IF(U15<26666.95,(((U15-13333.49)*16.5%)+1713.24),IF(U15<52000.54,(((U15-26666.95)*19%)+3913.26),IF(U15>52000.54,(((U15-52000.54)*22%)+8726.64),"ERRO")))))))) -> 821.1542 | W15: =IF(V15<7786.02,V15,((V15-7786.02)*8.5%)+7786.02) -> 821.1542 | X15: =M15 -> 2386.5233 | Y15: =IF(X15<1412.01,(105.9),IF(X15<2666.69,(((X15-1412.01)*9%)+105.9),IF(X15<4000.04,(((X15-2666.69)*12%)+218.82),IF(X15<7786.03,(((X15-4000.04)*14%)+378.82),IF(X15<13333.49,(((X15-7786.03)*14.5%)+908.86),IF(X15<26666.95,(((X15-13333.49)*16.5%)+1713.24),IF(X15<52000.54,(((X15-26666.95)*19%)+3913.26),IF(X15>52000.54,(((X15-52000.54)*22%)+8726.64),"ERRO")))))))) -> 193.6062 | Z15: =IF(Y15<7786.02,Y15,((Y15-7786.02)*8.5%)+7786.02) -> 193.6062 | AA15: =SUM(W15,Z15) -> 1014.7604
A16: Enfermeiro | B16: =INDEX(PERFIL!$C$2:$C$146,MATCH(CUSTO!A16,PERFIL!$B$2:$B$146,0)) -> NS | C16: =INDEX(PAINEL!$B$4:$B$100,MATCH($A16,PAINEL!$A$4:$A$100,0)) -> 5 | D16: 2769.57 | E16: 4390 | F16: =D16+E16 -> 7159.57 | G16: =T16 -> 821.1542 | H16: 1175 | I16: - | J16: =SUM(F16:I16) -> 9155.7242 | K16: =J16*12 -> 109868.69 | L16: =F16 -> 7159.57 | M16: =F16/3 -> 2386.5233 | N16: =AA16 -> 1014.7604 | O16: =SUM(K16:N16) -> 120429.54 | P16: =C16*O16 -> 602147.72 | Q16: CONFERIDO | R16: =F16 -> 7159.57 | S16: =IF(R16<1412.01,(105.9),IF(R16<2666.69,(((R16-1412.01)*9%)+105.9),IF(R16<4000.04,(((R16-2666.69)*12%)+218.82),IF(R16<7786.03,(((R16-4000.04)*14%)+378.82),IF(R16<13333.49,(((R16-7786.03)*14.5%)+908.86),IF(R16<26666.95,(((R16-13333.49)*16.5%)+1713.24),IF(R16<52000.54,(((R16-26666.95)*19%)+3913.26),IF(R16>52000.54,(((R16-52000.54)*22%)+8726.64),"ERRO")))))))) -> 821.1542 | T16: =IF(S16<7786.02,S16,((S16-7786.02)*8.5%)+7786.02) -> 821.1542 | U16: =L16 -> 7159.57 | V16: =IF(U16<1412.01,(105.9),IF(U16<2666.69,(((U16-1412.01)*9%)+105.9),IF(U16<4000.04,(((U16-2666.69)*12%)+218.82),IF(U16<7786.03,(((U16-4000.04)*14%)+378.82),IF(U16<13333.49,(((U16-7786.03)*14.5%)+908.86),IF(U16<26666.95,(((U16-13333.49)*16.5%)+1713.24),IF(U16<52000.54,(((U16-26666.95)*19%)+3913.26),IF(U16>52000.54,(((U16-52000.54)*22%)+8726.64),"ERRO")))))))) -> 821.1542 | W16: =IF(V16<7786.02,V16,((V16-7786.02)*8.5%)+7786.02) -> 821.1542 | X16: =M16 -> 2386.5233 | Y16: =IF(X16<1412.01,(105.9),IF(X16<2666.69,(((X16-1412.01)*9%)+105.9),IF(X16<4000.04,(((X16-2666.69)*12%)+218.82),IF(X16<7786.03,(((X16-4000.04)*14%)+378.82),IF(X16<13333.49,(((X16-7786.03)*14.5%)+908.86),IF(X16<26666.95,(((X16-13333.49)*16.5%)+1713.24),IF(X16<52000.54,(((X16-26666.95)*19%)+3913.26),IF(X16>52000.54,(((X16-52000.54)*22%)+8726.64),"ERRO")))))))) -> 193.6062 | Z16: =IF(Y16<7786.02,Y16,((Y16-7786.02)*8.5%)+7786.02) -> 193.6062 | AA16: =SUM(W16,Z16) -> 1014.7604
A17: Engenheiro Civil | B17: =INDEX(PERFIL!$C$2:$C$146,MATCH(CUSTO!A17,PERFIL!$B$2:$B$146,0)) -> NS | C17: =INDEX(PAINEL!$B$4:$B$100,MATCH($A17,PAINEL!$A$4:$A$100,0)) -> 1 | D17: 3755.5 | E17: =66.41*100 -> 6641 | F17: =D17+E17 -> 10396.5 | G17: =T17 -> 1287.3782 | H17: 1175 | I17: - | J17: =SUM(F17:I17) -> 12858.878 | K17: =J17*12 -> 154306.54 | L17: =F17 -> 10396.5 | M17: =F17/3 -> 3465.5 | N17: =AA17 -> 1602.0554 | O17: =SUM(K17:N17) -> 169770.59 | P17: =C17*O17 -> 169770.59 | Q17: CONFERIDO | R17: =F17 -> 10396.5 | S17: =IF(R17<1412.01,(105.9),IF(R17<2666.69,(((R17-1412.01)*9%)+105.9),IF(R17<4000.04,(((R17-2666.69)*12%)+218.82),IF(R17<7786.03,(((R17-4000.04)*14%)+378.82),IF(R17<13333.49,(((R17-7786.03)*14.5%)+908.86),IF(R17<26666.95,(((R17-13333.49)*16.5%)+1713.24),IF(R17<52000.54,(((R17-26666.95)*19%)+3913.26),IF(R17>52000.54,(((R17-52000.54)*22%)+8726.64),"ERRO")))))))) -> 1287.3782 | T17: =IF(S17<7786.02,S17,((S17-7786.02)*8.5%)+7786.02) -> 1287.3782 | U17: =L17 -> 10396.5 | V17: =IF(U17<1412.01,(105.9),IF(U17<2666.69,(((U17-1412.01)*9%)+105.9),IF(U17<4000.04,(((U17-2666.69)*12%)+218.82),IF(U17<7786.03,(((U17-4000.04)*14%)+378.82),IF(U17<13333.49,(((U17-7786.03)*14.5%)+908.86),IF(U17<26666.95,(((U17-13333.49)*16.5%)+1713.24),IF(U17<52000.54,(((U17-26666.95)*19%)+3913.26),IF(U17>52000.54,(((U17-52000.54)*22%)+8726.64),"ERRO")))))))) -> 1287.3782 | W17: =IF(V17<7786.02,V17,((V17-7786.02)*8.5%)+7786.02) -> 1287.3782 | X17: =M17 -> 3465.5 | Y17: =IF(X17<1412.01,(105.9),IF(X17<2666.69,(((X17-1412.01)*9%)+105.9),IF(X17<4000.04,(((X17-2666.69)*12%)+218.82),IF(X17<7786.03,(((X17-4000.04)*14%)+378.82),IF(X17<13333.49,(((X17-7786.03)*14.5%)+908.86),IF(X17<26666.95,(((X17-13333.49)*16.5%)+1713.24),IF(X17<52000.54,(((X17-26666.95)*19%)+3913.26),IF(X17>52000.54,(((X17-52000.54)*22%)+8726.64),"ERRO")))))))) -> 314.6772 | Z17: =IF(Y17<7786.02,Y17,((Y17-7786.02)*8.5%)+7786.02) -> 314.6772 | AA17: =SUM(W17,Z17) -> 1602.0554
A18: Engenheiro de Segurança do Trabalho | B18: =INDEX(PERFIL!$C$2:$C$146,MATCH(CUSTO!A18,PERFIL!$B$2:$B$146,0)) -> NS | C18: =INDEX(PAINEL!$B$4:$B$100,MATCH($A18,PAINEL!$A$4:$A$100,0)) -> 1 | D18: 3755.5 | E18: =66.41*100 -> 6641 | F18: =D18+E18 -> 10396.5 | G18: =T18 -> 1287.3782 | H18: 1175 | I18: - | J18: =SUM(F18:I18) -> 12858.878 | K18: =J18*12 -> 154306.54 | L18: =F18 -> 10396.5 | M18: =F18/3 -> 3465.5 | N18: =AA18 -> 1602.0554 | O18: =SUM(K18:N18) -> 169770.59 | P18: =C18*O18 -> 169770.59 | Q18: CONFERIDO | R18: =F18 -> 10396.5 | S18: =IF(R18<1412.01,(105.9),IF(R18<2666.69,(((R18-1412.01)*9%)+105.9),IF(R18<4000.04,(((R18-2666.69)*12%)+218.82),IF(R18<7786.03,(((R18-4000.04)*14%)+378.82),IF(R18<13333.49,(((R18-7786.03)*14.5%)+908.86),IF(R18<26666.95,(((R18-13333.49)*16.5%)+1713.24),IF(R18<52000.54,(((R18-26666.95)*19%)+3913.26),IF(R18>52000.54,(((R18-52000.54)*22%)+8726.64),"ERRO")))))))) -> 1287.3782 | T18: =IF(S18<7786.02,S18,((S18-7786.02)*8.5%)+7786.02) -> 1287.3782 | U18: =L18 -> 10396.5 | V18: =IF(U18<1412.01,(105.9),IF(U18<2666.69,(((U18-1412.01)*9%)+105.9),IF(U18<4000.04,(((U18-2666.69)*12%)+218.82),IF(U18<7786.03,(((U18-4000.04)*14%)+378.82),IF(U18<13333.49,(((U18-7786.03)*14.5%)+908.86),IF(U18<26666.95,(((U18-13333.49)*16.5%)+1713.24),IF(U18<52000.54,(((U18-26666.95)*19%)+3913.26),IF(U18>52000.54,(((U18-52000.54)*22%)+8726.64),"ERRO")))))))) -> 1287.3782 | W18: =IF(V18<7786.02,V18,((V18-7786.02)*8.5%)+7786.02) -> 1287.3782 | X18: =M18 -> 3465.5 | Y18: =IF(X18<1412.01,(105.9),IF(X18<2666.69,(((X18-1412.01)*9%)+105.9),IF(X18<4000.04,(((X18-2666.69)*12%)+218.82),IF(X18<7786.03,(((X18-4000.04)*14%)+378.82),IF(X18<13333.49,(((X18-7786.03)*14.5%)+908.86),IF(X18<26666.95,(((X18-13333.49)*16.5%)+1713.24),IF(X18<52000.54,(((X18-26666.95)*19%)+3913.26),IF(X18>52000.54,(((X18-52000.54)*22%)+8726.64),"ERRO")))))))) -> 314.6772 | Z18: =IF(Y18<7786.02,Y18,((Y18-7786.02)*8.5%)+7786.02) -> 314.6772 | AA18: =SUM(W18,Z18) -> 1602.0554
A19: Engenheiro Eletricista | B19: =INDEX(PERFIL!$C$2:$C$146,MATCH(CUSTO!A19,PERFIL!$B$2:$B$146,0)) -> NS | C19: =INDEX(PAINEL!$B$4:$B$100,MATCH($A19,PAINEL!$A$4:$A$100,0)) -> 1 | D19: 3755.5 | E19: =66.41*100 -> 6641 | F19: =D19+E19 -> 10396.5 | G19: =T19 -> 1287.3782 | H19: 1175 | I19: - | J19: =SUM(F19:I19) -> 12858.878 | K19: =J19*12 -> 154306.54 | L19: =F19 -> 10396.5 | M19: =F19/3 -> 3465.5 | N19: =AA19 -> 1602.0554 | O19: =SUM(K19:N19) -> 169770.59 | P19: =C19*O19 -> 169770.59 | Q19: CONFERIDO | R19: =F19 -> 10396.5 | S19: =IF(R19<1412.01,(105.9),IF(R19<2666.69,(((R19-1412.01)*9%)+105.9),IF(R19<4000.04,(((R19-2666.69)*12%)+218.82),IF(R19<7786.03,(((R19-4000.04)*14%)+378.82),IF(R19<13333.49,(((R19-7786.03)*14.5%)+908.86),IF(R19<26666.95,(((R19-13333.49)*16.5%)+1713.24),IF(R19<52000.54,(((R19-26666.95)*19%)+3913.26),IF(R19>52000.54,(((R19-52000.54)*22%)+8726.64),"ERRO")))))))) -> 1287.3782 | T19: =IF(S19<7786.02,S19,((S19-7786.02)*8.5%)+7786.02) -> 1287.3782 | U19: =L19 -> 10396.5 | V19: =IF(U19<1412.01,(105.9),IF(U19<2666.69,(((U19-1412.01)*9%)+105.9),IF(U19<4000.04,(((U19-2666.69)*12%)+218.82),IF(U19<7786.03,(((U19-4000.04)*14%)+378.82),IF(U19<13333.49,(((U19-7786.03)*14.5%)+908.86),IF(U19<26666.95,(((U19-13333.49)*16.5%)+1713.24),IF(U19<52000.54,(((U19-26666.95)*19%)+3913.26),IF(U19>52000.54,(((U19-52000.54)*22%)+8726.64),"ERRO")))))))) -> 1287.3782 | W19: =IF(V19<7786.02,V19,((V19-7786.02)*8.5%)+7786.02) -> 1287.3782 | X19: =M19 -> 3465.5 | Y19: =IF(X19<1412.01,(105.9),IF(X19<2666.69,(((X19-1412.01)*9%)+105.9),IF(X19<4000.04,(((X19-2666.69)*12%)+218.82),IF(X19<7786.03,(((X19-4000.04)*14%)+378.82),IF(X19<13333.49,(((X19-7786.03)*14.5%)+908.86),IF(X19<26666.95,(((X19-13333.49)*16.5%)+1713.24),IF(X19<52000.54,(((X19-26666.95)*19%)+3913.26),IF(X19>52000.54,(((X19-52000.54)*22%)+8726.64),"ERRO")))))))) -> 314.6772 | Z19: =IF(Y19<7786.02,Y19,((Y19-7786.02)*8.5%)+7786.02) -> 314.6772 | AA19: =SUM(W19,Z19) -> 1602.0554
A20: Estatístico | B20: =INDEX(PERFIL!$C$2:$C$146,MATCH(CUSTO!A20,PERFIL!$B$2:$B$146,0)) -> NS | C20: =INDEX(PAINEL!$B$4:$B$100,MATCH($A20,PAINEL!$A$4:$A$100,0)) -> 3 | D20: 3755.5 | E20: =66.41*100 -> 6641 | F20: =D20+E20 -> 10396.5 | G20: =T20 -> 1287.3782 | H20: 1175 | I20: - | J20: =SUM(F20:I20) -> 12858.878 | K20: =J20*12 -> 154306.54 | L20: =F20 -> 10396.5 | M20: =F20/3 -> 3465.5 | N20: =AA20 -> 1602.0554 | O20: =SUM(K20:N20) -> 169770.59 | P20: =C20*O20 -> 509311.78 | Q20: CONFERIDO | R20: =F20 -> 10396.5 | S20: =IF(R20<1412.01,(105.9),IF(R20<2666.69,(((R20-1412.01)*9%)+105.9),IF(R20<4000.04,(((R20-2666.69)*12%)+218.82),IF(R20<7786.03,(((R20-4000.04)*14%)+378.82),IF(R20<13333.49,(((R20-7786.03)*14.5%)+908.86),IF(R20<26666.95,(((R20-13333.49)*16.5%)+1713.24),IF(R20<52000.54,(((R20-26666.95)*19%)+3913.26),IF(R20>52000.54,(((R20-52000.54)*22%)+8726.64),"ERRO")))))))) -> 1287.3782 | T20: =IF(S20<7786.02,S20,((S20-7786.02)*8.5%)+7786.02) -> 1287.3782 | U20: =L20 -> 10396.5 | V20: =IF(U20<1412.01,(105.9),IF(U20<2666.69,(((U20-1412.01)*9%)+105.9),IF(U20<4000.04,(((U20-2666.69)*12%)+218.82),IF(U20<7786.03,(((U20-4000.04)*14%)+378.82),IF(U20<13333.49,(((U20-7786.03)*14.5%)+908.86),IF(U20<26666.95,(((U20-13333.49)*16.5%)+1713.24),IF(U20<52000.54,(((U20-26666.95)*19%)+3913.26),IF(U20>52000.54,(((U20-52000.54)*22%)+8726.64),"ERRO")))))))) -> 1287.3782 | W20: =IF(V20<7786.02,V20,((V20-7786.02)*8.5%)+7786.02) -> 1287.3782 | X20: =M20 -> 3465.5 | Y20: =IF(X20<1412.01,(105.9),IF(X20<2666.69,(((X20-1412.01)*9%)+105.9),IF(X20<4000.04,(((X20-2666.69)*12%)+218.82),IF(X20<7786.03,(((X20-4000.04)*14%)+378.82),IF(X20<13333.49,(((X20-7786.03)*14.5%)+908.86),IF(X20<26666.95,(((X20-13333.49)*16.5%)+1713.24),IF(X20<52000.54,(((X20-26666.95)*19%)+3913.26),IF(X20>52000.54,(((X20-52000.54)*22%)+8726.64),"ERRO")))))))) -> 314.6772 | Z20: =IF(Y20<7786.02,Y20,((Y20-7786.02)*8.5%)+7786.02) -> 314.6772 | AA20: =SUM(W20,Z20) -> 1602.0554
A21: Farmacêutico Bioquímico | B21: =INDEX(PERFIL!$C$2:$C$146,MATCH(CUSTO!A21,PERFIL!$B$2:$B$146,0)) -> NS | C21: =INDEX(PAINEL!$B$4:$B$100,MATCH($A21,PAINEL!$A$4:$A$100,0)) -> 2 | D21: 2769.57 | E21: 4390 | F21: =D21+E21 -> 7159.57 | G21: =T21 -> 821.1542 | H21: 1175 | I21: - | J21: =SUM(F21:I21) -> 9155.7242 | K21: =J21*12 -> 109868.69 | L21: =F21 -> 7159.57 | M21: =F21/3 -> 2386.5233 | N21: =AA21 -> 1014.7604 | O21: =SUM(K21:N21) -> 120429.54 | P21: =C21*O21 -> 240859.09 | Q21: CONFERIDO | R21: =F21 -> 7159.57 | S21: =IF(R21<1412.01,(105.9),IF(R21<2666.69,(((R21-1412.01)*9%)+105.9),IF(R21<4000.04,(((R21-2666.69)*12%)+218.82),IF(R21<7786.03,(((R21-4000.04)*14%)+378.82),IF(R21<13333.49,(((R21-7786.03)*14.5%)+908.86),IF(R21<26666.95,(((R21-13333.49)*16.5%)+1713.24),IF(R21<52000.54,(((R21-26666.95)*19%)+3913.26),IF(R21>52000.54,(((R21-52000.54)*22%)+8726.64),"ERRO")))))))) -> 821.1542 | T21: =IF(S21<7786.02,S21,((S21-7786.02)*8.5%)+7786.02) -> 821.1542 | U21: =L21 -> 7159.57 | V21: =IF(U21<1412.01,(105.9),IF(U21<2666.69,(((U21-1412.01)*9%)+105.9),IF(U21<4000.04,(((U21-2666.69)*12%)+218.82),IF(U21<7786.03,(((U21-4000.04)*14%)+378.82),IF(U21<13333.49,(((U21-7786.03)*14.5%)+908.86),IF(U21<26666.95,(((U21-13333.49)*16.5%)+1713.24),IF(U21<52000.54,(((U21-26666.95)*19%)+3913.26),IF(U21>52000.54,(((U21-52000.54)*22%)+8726.64),"ERRO")))))))) -> 821.1542 | W21: =IF(V21<7786.02,V21,((V21-7786.02)*8.5%)+7786.02) -> 821.1542 | X21: =M21 -> 2386.5233 | Y21: =IF(X21<1412.01,(105.9),IF(X21<2666.69,(((X21-1412.01)*9%)+105.9),IF(X21<4000.04,(((X21-2666.69)*12%)+218.82),IF(X21<7786.03,(((X21-4000.04)*14%)+378.82),IF(X21<13333.49,(((X21-7786.03)*14.5%)+908.86),IF(X21<26666.95,(((X21-13333.49)*16.5%)+1713.24),IF(X21<52000.54,(((X21-26666.95)*19%)+3913.26),IF(X21>52000.54,(((X21-52000.54)*22%)+8726.64),"ERRO")))))))) -> 193.6062 | Z21: =IF(Y21<7786.02,Y21,((Y21-7786.02)*8.5%)+7786.02) -> 193.6062 | AA21: =SUM(W21,Z21) -> 1014.7604
A22: Fisioterapeuta | B22: =INDEX(PERFIL!$C$2:$C$146,MATCH(CUSTO!A22,PERFIL!$B$2:$B$146,0)) -> NS | C22: =INDEX(PAINEL!$B$4:$B$100,MATCH($A22,PAINEL!$A$4:$A$100,0)) -> 3 | D22: 2769.57 | E22: 4390 | F22: =D22+E22 -> 7159.57 | G22: =T22 -> 821.1542 | H22: 1175 | I22: - | J22: =SUM(F22:I22) -> 9155.7242 | K22: =J22*12 -> 109868.69 | L22: =F22 -> 7159.57 | M22: =F22/3 -> 2386.5233 | N22: =AA22 -> 1014.7604 | O22: =SUM(K22:N22) -> 120429.54 | P22: =C22*O22 -> 361288.63 | Q22: CONFERIDO | R22: =F22 -> 7159.57 | S22: =IF(R22<1412.01,(105.9),IF(R22<2666.69,(((R22-1412.01)*9%)+105.9),IF(R22<4000.04,(((R22-2666.69)*12%)+218.82),IF(R22<7786.03,(((R22-4000.04)*14%)+378.82),IF(R22<13333.49,(((R22-7786.03)*14.5%)+908.86),IF(R22<26666.95,(((R22-13333.49)*16.5%)+1713.24),IF(R22<52000.54,(((R22-26666.95)*19%)+3913.26),IF(R22>52000.54,(((R22-52000.54)*22%)+8726.64),"ERRO")))))))) -> 821.1542 | T22: =IF(S22<7786.02,S22,((S22-7786.02)*8.5%)+7786.02) -> 821.1542 | U22: =L22 -> 7159.57 | V22: =IF(U22<1412.01,(105.9),IF(U22<2666.69,(((U22-1412.01)*9%)+105.9),IF(U22<4000.04,(((U22-2666.69)*12%)+218.82),IF(U22<7786.03,(((U22-4000.04)*14%)+378.82),IF(U22<13333.49,(((U22-7786.03)*14.5%)+908.86),IF(U22<26666.95,(((U22-13333.49)*16.5%)+1713.24),IF(U22<52000.54,(((U22-26666.95)*19%)+3913.26),IF(U22>52000.54,(((U22-52000.54)*22%)+8726.64),"ERRO")))))))) -> 821.1542 | W22: =IF(V22<7786.02,V22,((V22-7786.02)*8.5%)+7786.02) -> 821.1542 | X22: =M22 -> 2386.5233 | Y22: =IF(X22<1412.01,(105.9),IF(X22<2666.69,(((X22-1412.01)*9%)+105.9),IF(X22<4000.04,(((X22-2666.69)*12%)+218.82),IF(X22<7786.03,(((X22-4000.04)*14%)+378.82),IF(X22<13333.49,(((X22-7786.03)*14.5%)+908.86),IF(X22<26666.95,(((X22-13333.49)*16.5%)+1713.24),IF(X22<52000.54,(((X22-26666.95)*19%)+3913.26),IF(X22>52000.54,(((X22-52000.54)*22%)+8726.64),"ERRO")))))))) -> 193.6062 | Z22: =IF(Y22<7786.02,Y22,((Y22-7786.02)*8.5%)+7786.02) -> 193.6062 | AA22: =SUM(W22,Z22) -> 1014.7604
